Workbook
Name Age: Data!$D$45
Name Inflation: Assumptions!$F$3
Name PlanDate: Data!$G$34
Name scores: 'Risk Profile'!$L$5:$M$8
Name Wifeage: Data!$F$45

Sheet Data
I1: Consultant's Notes
B2: Data Gathering Form
B7: S.No. | C7: Guidelines for Client to fill the Data Gathering Form
B8: 1 | C8: Fill the form under the guidance of a Qualified Personal Finance Professional.
B9: 2 | C9: Fill the form accurately and completely to the best of your knowledge.
B10: 3 | C10: Involve your spouse in the process and mutually agree upon the data provided.
B11: 4 | C11: Mention NA (Not Applicable) for questions that do not relate to your circumstances.
B12: 5 | C12: Present & Provide photocopy of supporting documents wherever possible/required.
B14: Confidentiality of Data & Documents
B15: As a Professional, we assure you that the data and documents provided by you during the course of financial consultancy process will be kept confidential at all times.
B18: S. No. | C18: Sections of the Data Gathering Form
B19: 1 | C19: Client Details - Personal, Family & Communication Details
B20: 3 | C20: Major Goals - Children's Future, House Purchase, Retirement, Car, Vacations
B21: 4 | C21: Other Goals, High-end Goals & Financial Well-being
B22: 5 | C22: Income - Salary, Bonus, Business, Rental etc
B23: 6 | C23: Expenditures - Household & Lifestyle Expenses, Insurance Premiums etc
B24: 7 | C24: Regular Investments - RDs, SIPs, Insurance Premiums, PPF/EPF
B25: 8 | C25: Insurance Policies - Life Insurance, General Insurance
B26: 9 | C26: Employment Benefits - EPF, Gratuity, Group Insurance etc
B27: 10 | C27: Investment Assets - Liquid, Debt, Equity, Gold, Real Estate
B28: 11 | C28: Personal Assets - House, Car & Jewellery
B29: 12 | C29: Personal Liabilities - Home Loan, Vehicle Loan, Personal Loan
B30: 13 | C30: Assumptions - Inflation, Income Growth, Returns, Loan Rates etc
B31: 15 | C31: Documents Submission & Declaration
B33: Client Details
B34: Client Name | F34: Current Date
B35: Consultant Name | D35: Nikhil Tandulwadikar | F35: Client Code
B37: Personal Details
B38: Particulars | D38: Husband | F38: Wife | G38: Wife
B39: Name
B40: Work Details | C40: Work Details | K40: Private Salaried
B41: Designation | C41: Designation | K41: Business
B42: Company | C42: Company | K42: Government
B43: Health History | C43: Health History | K43: Professional
B44: Date of Birth dd/mm/yy | C44: Date of Birth (dd/mm/yy) | K44: Retired
B45: Current Age | C45: Current Age | D45: =(PlanDate-D44)/365 -> 0 | F45: =(PlanDate-F44)/365 -> 0 | K45: Homemaker
K46: NA
B47: Family Details | C47: Family Details
B48: Particulars | D48: Child-1 | E48: Child-2 | F48: Father | G48: Mother | K48: PED
B49: Name | K49: Normal
...

Sheet Risk Profile
A1: Investor Risk Profile Questionnaire
A2: Sr. No. | B2: Question to Investors | G2: Answer | H2: Score
A3: 1 | B3: If the performance of an investment you have recently made is below your expectations or in negative, how would you feel?
A4: a | B4: Very upset | G4: b | H4: =VLOOKUP(G4,scores,2,FALSE) -> 20
A5: b | B5: Somewhat upset, but hope that it will improve in the future | L5: a | M5: 10
A6: c | B6: Uneasy but willing to take it in my stride | L6: b | M6: 20
A7: d | B7: Not upset because I know that all investments carry risk | L7: c | M7: 30
A8: 2 | B8: What do you normally associate the word 'Risk' with? | L8: d | M8: 40
A9: a | B9: Danger | G9: b | H9: =VLOOKUP(G9,scores,2,FALSE) -> 20
A10: b | B10: Uncertainty
A11: c | B11: Opportunity
A12: d | B12: Thrill
A13: 3 | B13: If you had to choose between being a salaried employee and running your own business, which one would you prefer?
A14: a | B14: Being a salaried employee | G14: c | H14: =VLOOKUP(G14,scores,2,FALSE) -> 30
A15: b | B15: Doing a salaried job and may be run a part-time business
A16: c | B16: Running a partnership business
A17: d | B17: Running my own business
A18: 4 | B18: When you invest your money in any instrument, what thought comes to your mind first?
A19: a | B19: I should not lose my money | G19: c | H19: =VLOOKUP(G19,scores,2,FALSE) -> 30
A20: b | B20: This should not turn out to be a bad investment
A21: c | B21: This should turn out to be a good investment
A22: d | B22: I know this is a good decision
A23: 5 | B23: After you have made an investment, how do you usually feel?
A24: a | B24: Very worried | G24: b | H24: =VLOOKUP(G24,scores,2,FALSE) -> 20
A25: b | B25: Somewhat worried
A26: c | B26: Somewhat satisfied
A27: d | B27: Very satisfied
A28: 6 | B28: If you had the choice between a fixed salary and a partly variable one, depending on your performance and the profits of your company, which one would you prefer?
A29: a | B29: I would prefer a fixed salary, even if it is small | G29: d | H29: =VLOOKUP(G29,scores,2,FALSE) -> 40
A30: b | B30: I would prefer most of my salary to be fixed, with only a small variable part
A31: c | B31: I would prefer half my salary to be fixed and the other half to be variable
A32: d | B32: I would prefer most of my earnings to be performance-linked
A33: 7 | B33: If you had to make an investment decision without consulting or discussing it with anybody, how would you feel?
A34: a | B34: Very unsure | G34: b | H34: =VLOOKUP(G34,scores,2,FALSE) -> 20
A35: b | B35: Not very confident
A36: c | B36: Some what confident
A37: d | B37: Very confident
A38: 8 | B38: Experts tell you that investments are subject to risk and you have to be prepared for losses as well as gains. What is the level of loss in your investment that you are willing to accept?
A39: a | B39: I would hate to see any kind of loss in my investments | G39: c | H39: =VLOOKUP(G39,scores,2,FALSE) -> 30
A40: b | B40: I will be willing to take up to a 20% loss
...

Sheet Cover
B2: Prepared on: | C2: =PlanDate -> 0 | D2: Strictly Private & Confidential
B10: Comprehensive Financial Blueprint of
B11: =CONCATENATE(Data!D34," & Family") -> & Family
B33: =Data!D35 -> Nikhil Tandulwadikar
B34: Certified Financial Planner®, AMFI-registered Mutual Fund Distributor
B35: 352, A to Z Estate, G K Marg, Lower Parel - 400 013
B36: Mobile: 9885208018, Email: kevalinvest@gmail.com, Website: www.kevalinvest.com

Sheet Letter
B3: =PlanDate -> 0
B5: =Data!D34 -> 0
B6: =Data!D60 -> 0
B7: =Data!E60 -> 0
B8: =Data!F60 -> 0
B9: =Data!G60 -> 0
B11: =CONCATENATE("Dear Mr. ",B5) -> Dear Mr. 0
B13: Thank you for giving us an opportunity to prepare your personal finance blueprint. We appreciate your proactive approach in achieving financial goals, fulfilling family commitments and also take control of your personal finance matters.
B14: The enclosed comprehensive personal finance blueprint of your family analyse your current financial situation & future financial goals and provides recommendations and an action plan to bridge the gap between two by addressing them on a timely basis.
B15: The blueprint is prepared based on the information provided by you of your current circumstances and future objectives. Please read it carefully to check for accuracy of the information provided. However, it needs to be monitored on an ongoing basis and updated in response to changes in your own circumstances and other factors such as government regulations, market movements and macro economy.
B16: We shall be glad to provide you with our ongoing services to implement & monitor your financial blueprint to ensure you meet your financial goals. Kindly read our disclaimer & disclosure on the last page. Please feel free to contact us if you need any clarifications or information.
B18: Thanking you once again
B19: Yours Sincerely
B21: ____________________
B22: =Cover!$B$33 -> Nikhil Tandulwadikar
B23: =Cover!B34 -> Certified Financial Planner®, AMFI-registered Mutual Fund Distributor

Sheet Contents
B1: Table of Contents
B2: S. No. | C2: Section | D2: Page No.
C3: Executive Summary | D3: 4
B4: 1 | C4: Family Details | D4: 5
B5: 2 | C5: Client Goals & Objectives | D5: 6
B6: 3 | C6: Goal Funding Map | D6: 7
B7: 4 | C7: One Year Action Plan | D7: 8
C8: Current Financials | D8: 9
B9: 1 | C9: Income Expenditure Statement (Cashflows) | D9: 10-11
B10: 2 | C10: Assets & Liabilities Statement (Networth) | D10: 12-13
B11: 3 | C11: General Insurance Policies | D11: 14
B12: 4 | C12: Life Insurance Policies | D12: 15
B13: 5 | C13: Fixed Deposits & Debt Instruments | D13: 16
B14: 6 | C14: Mutual Funds | D14: 17
B15: 7 | C15: Equity Shares | D15: 18
C16: Future Goals | D16: 19
B17: 1 | C17: Financial Plan Assumptions | D17: 20
B18: 2 | C18: Life Insurance Needs | D18: 21
B19: 3 | C19: Complete Insurance Portfolio | D19: 22
B20: 4 | C20: Contingency Funding | D20: 23
B21: 5 | C21: =CONCATENATE("Child 1 Future"," - ",Family!F2) -> Child 1 Future - Child-1 | D21: 24
B22: 6 | C22: =CONCATENATE("Child 2 Future"," - ",Family!G2) -> Child 2 Future - Child-2 | D22: 25
B23: 7 | C23: Retirement Consultancy | D23: 26
B24: 8 | C24: House Purchase | D24: 27
B25: 9 | C25: Car Purchase | D25: 28
B26: 10 | C26: International Vacation | D26: 29
C27: Life Cashflows | D27: 30
B28: 1 | C28: Disclaimer & Discloser | D28: 31
B29: Other Calculators / Templates
B30: S. No. | C30: Section | D30: Page No.
B31: 1 | C31: Any Other Goals
B32: 2 | C32: Employment Benefits - EPF, Pension, Gratuity, SA, PF
B33: 3 | C33: Risk Profile Results
B34: 4 | C34: EMI Calculator
B35: 5 | C35: Income Tax Calculator
B36: 6 | C36: Financial Ratios
B37: 7 | C37: Asset-Goal Mapping Assistant
B38: 8 | C38: Insurance Cashflows
B39: 9 | C39: Time Value of Money
B40: 10 | C40: IRR/XIRR Calculator
...

Sheet Executive
A1: Executive Summary
B20: S. No. | C20: Section Contents
B21: 1 | C21: =Contents!C4 -> Family Details
B22: 2 | C22: =Contents!C5 -> Client Goals & Objectives
B23: 3 | C23: =Contents!C6 -> Goal Funding Map
B24: 4 | C24: =Contents!C7 -> One Year Action Plan

Sheet Family
B1: Family Details & Goals
B2: Particulars | D2: Husband | E2: Wife | F2: Child-1 | G2: Child-2 | H2: Father | I2: Mother | J2: List of Potential Client Goals
B3: Name | D3: =Data!D39 -> 0 | E3: =Data!F39 -> 0 | F3: =Data!D49 -> 0 | G3: =Data!E49 -> 0 | H3: =Data!F49 -> 0 | I3: =Data!G49 -> 0
B4: Date of Birth | D4: =Data!D44 -> 0 | E4: =Data!F44 -> 0 | F4: =Data!D53 -> 0 | G4: =Data!E53 -> 0 | H4: =Data!F53 -> 0 | I4: =Data!G53 -> 0 | J4: 1 | K4: Emergency Funding
B5: Current Age | D5: =Data!D45 -> 0 | E5: =Data!F45 -> 0 | F5: =Data!D54 -> 0 | G5: =Data!E54 -> 0 | H5: =Data!F54 -> 0 | I5: =Data!G54 -> 0 | J5: 2 | K5: Retirement Funds
J6: 3 | K6: Children’s Education
J7: 4 | K7: House Purchase
D8: Short-Term Goals | F8: Medium-Term Goals | H8: Long Term Goals | J8: 5 | K8: International Vacations
D9: Less than 2 Years | F9: 2-7 Years | H9: More than 7 Years | J9: 6 | K9: Car Purchase
B10: Needs | C10: High-Priority | J10: 7 | K10: Children’s Marriage
J11: 8 | K11: New Venture / Start Up
J12: 9 | K12: Sabbatical from Work
J13: 10 | K13: Home Renovation
J14: 11 | K14: Holiday Home
D15: 1 | F15: 2 | H15: 3 | J15: 12 | K15: Parents Medical Fund
B16: Wants | C16: Medium Priority | J16: 13 | K16: Self-Higher Education
J17: 14 | K17: Club Memberships
J18: 15 | K18: Learn a Hobby
J19: 16 | K19: Charity / Social Work
J20: 17 | K20: Legacy Wealth
D21: 4 | F21: 5 | H21: 6 | J21: 18 | K21: Big Purchases
B22: Dreams | C22: Low Priority | J22: 19 | K22: Life Insurance
J23: 20 | K23: Health Insurance
J24: 21
J25: 22
J26: 23
D27: 7 | F27: 8 | H27: 9 | J27: 24
J28: 25

Sheet Goals
B1: Client Goals & Consultant Comments
B2: Family Goals | C2: Planner Comments
B3: =CONCATENATE(Family!F3,"'s ","Future") -> 0's Future
B4: =Child1!B3 -> You would like to arrange 10 Lakhs for Graduation at 18 and 10 lakhs for his PG at 22 and 5 lakhs for Marriage at 26 in today's value. | C4: =Child1!B34 -> 0
B5: =CONCATENATE(Family!G3,"'s ","Future") -> 0's Future
B6: =Child2!B3 -> You would like to arrange 10 Lakhs for Graduation at 18 and 10 lakhs for her PG at 22 and 5 lakhs for Marriage at 26 in today's value. | C6: =Child2!B32 -> 0
B7: Retirement Corpus
B8: =Retirement!B3 -> You would like to accumulate an investment corpus to fund your retirement expenses from age 60 to 80. | C8: =Retirement!B47 -> 0
B9: House Purchase
B10: =House!B3 -> You would like to purchase a 2 BHK flat in the next 4 years costing around 60 lakhs in today's value in Navi Mumbai | C10: =House!B45 -> 0
B11: Life Insurance
B12: =Life!B3 -> You would like to protect your family's lifestyle, fulfil current liabilities and commitments in case of pre-mature death. | C12: =Life!B41 -> 0
B13: Health/General Insurance
B14: =General!B3 -> Your family would like to get insured for all possible emergencies in the most cost effective way so that your family is financially secured in case of unforseen situation. | C14: =General!B17 -> 0
B15: Car Purchase
B16: =Car!B3 -> Your family would like to purchase a car in the next 6 years costing around 8 lakhs in today's value. | C16: =Car!B38 -> 0
B17: International Vacation
B18: =Vacation!B3 -> Your family would like to go on an international vacation in the next 4 years costing around 3 lakhs in today's value | C18: =Vacation!B27 -> 0

Sheet Funding
B1: Goal Funding Map
B2: S No. | C2: Particulars | D2: Present Value | E2: No of Yrs | F2: Future Value | G2: Current Assets | H2: Future Value Of Current Assets | I2: Lumpsum Funding Required | J2: Fixed Funding | K2: Step Up Funding
B3: =Goals!B3 -> 0's Future
B4: 1 | C4: =CONCATENATE(Family!F3," - ","Graduation") -> 0 - Graduation | D4: =Child1!D8 -> 0 | E4: =Child1!D11 -> 0 | F4: =Child1!D15 -> 0 | H4: =Child1!D22 -> 0 | I4: =Child1!D28 -> 0 | J4: =Child1!D29 -> #NUM! | K4: =Child1!D31 -> #DIV/0!
B5: 2 | C5: =CONCATENATE(Family!F3," - ","Post Grad") -> 0 - Post Grad | D5: =Child1!E8 -> 0 | E5: =Child1!E11 -> 0 | F5: =Child1!E15 -> 0 | H5: =Child1!E22 -> 0 | I5: =Child1!E28 -> 0 | J5: =Child1!E29 -> #NUM! | K5: =Child1!E31 -> #DIV/0!
B6: 3 | C6: =CONCATENATE(Family!F3," - ","Marriage") -> 0 - Marriage | D6: =Child1!F8 -> 0 | E6: =Child1!F11 -> 0 | F6: =Child1!F15 -> 0 | H6: =Child1!F22 -> 0 | I6: =Child1!F28 -> 0 | J6: =Child1!F29 -> #NUM! | K6: =Child1!F31 -> #DIV/0!
C7: Total | D7: =SUM(D4:D6) -> 0 | F7: =SUM(F4:F6) -> 0 | H7: =SUM(H4:H6) -> 0 | I7: =SUM(I4:I6) -> 0 | J7: =SUM(J4:J6) -> #NUM! | K7: =SUM(K4:K6) -> #DIV/0!
B8: =Goals!B5 -> 0's Future
B9: 4 | C9: =CONCATENATE(Family!G3," - ","Graduation") -> 0 - Graduation | D9: =Child2!D8 -> 0 | E9: =Child2!D11 -> 0 | F9: =Child2!D15 -> 0 | H9: =Child2!D20 -> 0 | I9: =Child2!D26 -> 0 | J9: =Child2!D27 -> #NUM! | K9: =Child2!D29 -> #DIV/0!
B10: 5 | C10: =CONCATENATE(Family!G3," - ","Post Grad") -> 0 - Post Grad | D10: =Child2!E8 -> 0 | E10: =Child2!E11 -> 0 | F10: =Child2!E15 -> 0 | H10: =Child2!E20 -> 0 | I10: =Child2!E26 -> 0 | J10: =Child2!E27 -> #NUM! | K10: =Child2!E29 -> #DIV/0!
B11: 6 | C11: =CONCATENATE(Family!G3," - ","Marriage") -> 0 - Marriage | D11: =Child2!F8 -> 0 | E11: =Child2!F11 -> 0 | F11: =Child2!F15 -> 0 | H11: =Child2!F20 -> 0 | I11: =Child2!F26 -> 0 | J11: =Child2!F27 -> #NUM! | K11: =Child2!F29 -> #DIV/0!
C12: Total | D12: =SUM(D4:D11) -> 0 | F12: =SUM(F9:F11) -> 0 | H12: =SUM(H9:H11) -> 0 | I12: =SUM(I9:I11) -> 0 | J12: =SUM(J9:J11) -> #NUM! | K12: =SUM(K9:K11) -> #DIV/0!
B13: Retirement Corpus
B14: 7 | C14: Retirement Corpus | D14: NA | E14: =Retirement!D17 -> 0 | F14: =Retirement!D30 -> 0 | H14: =Retirement!D35 -> 0 | I14: =Retirement!D41 -> 0 | J14: =Retirement!D42 -> #NUM! | K14: =Retirement!D44 -> #DIV/0!
B15: House Purchase
B16: 8 | C16: Downpayment | D16: =House!D10 -> 0 | E16: =House!D12 -> 0 | F16: =House!D19 -> 0 | H16: =House!D33 -> 0 | I16: =House!D39 -> 0 | J16: =House!D40 -> #NUM! | K16: =House!D42 -> #DIV/0!
C17: Loan Funding | E17: =House!D27 -> 20 | F17: =House!D17 -> 0 | H17: NA | J17: =House!D28 -> 0 | K17: =House!D28 -> 0
C18: Total | D18: =House!D10 -> 0 | F18: =SUM(F16:F17) -> 0 | H18: =SUM(H16:H17) -> 0
B19: Car Purchase
B20: 9 | C20: Downpayment | D20: =Car!D8 -> 0 | E20: =Car!D10 -> 0 | F20: =Car!D12 -> 0 | H20: =Car!D26 -> 0 | I20: =Car!D32 -> 0 | J20: =Car!D33 -> #NUM! | K20: =Car!D35 -> #DIV/0!
C21: Loan Funding | E21: =Car!D20 -> 5 | F21: =Car!D15 -> 0 | H21: NA | J21: =Car!D21 -> 0 | K21: =Car!D21 -> 0
C22: Total | D22: =Car!D8 -> 0 | F22: =SUM(F20:F21) -> 0 | H22: =SUM(H20:H21) -> 0
B23: International Vacation
B24: 10 | C24: Int Vacation | D24: =Vacation!D8 -> 0 | E24: =Vacation!D10 -> 0 | F24: =Vacation!D11 -> 0 | H24: =Vacation!D15 -> 0 | I24: =Vacation!D21 -> 0 | J24: =Vacation!D22 -> #NUM! | K24: =Vacation!D24 -> #DIV/0!
I25: =I7+I12+I14+I18+I22+I24 -> 0 | J25: =J24+J20+J16+J14+J12+J7 -> #NUM! | K25: =K24+K20+K16+K14+K12+K7 -> #DIV/0!

Sheet Action
B1: One Year Action Plan
B2: S No | C2: What | D2: Why | E2: Who | F2: When
B3: General
B10: Insurance
B13: Investments

Sheet Current
A1: Current Financials
B19: Contents
B20: S. No. | C20: Section
B21: 1 | C21: =Contents!C9 -> Income Expenditure Statement (Cashflows)
B22: 2 | C22: =Contents!C10 -> Assets & Liabilities Statement (Networth)
B23: 3 | C23: =Contents!C11 -> General Insurance Policies
B24: 4 | C24: =Contents!C12 -> Life Insurance Policies
B25: 5 | C25: =Contents!C13 -> Fixed Deposits & Debt Instruments
B26: 6 | C26: =Contents!C14 -> Mutual Funds
B27: 7 | C27: =Contents!C15 -> Equity Shares

Sheet Cashflow
B1: Cashflow Statement
B2: Income (Net of Taxes)
B3: S.No. | C3: Annual Incomes | D3: Monthly | E3: Annual | F3: % of Income
B4: 1 | C4: Salary Income | D4: =E4/12 -> 0 | E4: =Data!G147 -> 0
B5: 2 | C5: Performance Bonus | D5: =E5/12 -> 0 | E5: =Data!G148 -> 0
B6: 3 | C6: Business Income | D6: =E6/12 -> 0 | E6: =Data!G149 -> 0
B7: 4 | C7: Rental Income | D7: =E7/12 -> 0 | E7: =Data!G150 -> 0
B8: 5 | C8: Investment Income | D8: =E8/12 -> 0 | E8: =Data!G151 -> 0
C9: Total Income | D9: =SUM(D4:D8) -> 0 | E9: =SUM(E4:E8) -> 0 | F9: =E9/E9 -> #DIV/0!
B11: Regular Investments
B12: S.No. | C12: Particulars | D12: Monthly | E12: Annual | F12: % of Income
B13: 1 | C13: Insurance Premiums (Investments) | D13: =Data!E192 -> 0 | E13: =Data!F192 -> 0
B14: 2 | C14: Mutual Fund SIPs | D14: =Data!E193 -> 0 | E14: =Data!F193 -> 0
B15: 3 | C15: Recurring Deposits (RDs) | D15: =Data!E194 -> 0 | E15: =Data!F194 -> 0
B16: 4 | C16: PPF/EPF | D16: =Data!E195 -> 0 | E16: =Data!F195 -> 0
B17: 5 | C17: Others | D17: =Data!E196 -> 0 | E17: =Data!F196 -> 0
B18: Regular Monthly Investments | D18: =SUM(D13:D17) -> 0 | E18: =SUM(E13:E17) -> 0 | F18: =Data!G197 -> #DIV/0!
B19: Potential for Additional Reg Investments | D19: =D55-D18 -> 0 | E19: =E55-E18 -> 0 | F19: =F55-F18 -> #DIV/0!
B22: Expenditures | C22: Outflows
B23: S.No. | C23: Particulars | D23: Monthly | E23: Annual | F23: % of Income
B24: Household Expenses
B25: 1 | C25: Grocery & Toiletaries | D25: =Data!E158 -> 0 | E25: =Data!F158 -> 0
B26: 2 | C26: House - Rent, Maintenance, Repair | D26: =Data!E159 -> 0 | E26: =Data!F159 -> 0
B27: 3 | C27: Conveyance, Fuel & Maintenance | D27: =Data!E160 -> 0 | E27: =Data!F160 -> 0
B28: 4 | C28: Medicines / Doctor / Healthcare | D28: =Data!E161 -> 0 | E28: =Data!F161 -> 0
B29: 5 | C29: Electricity / Water / Labour / AMCs | D29: =Data!E162 -> 0 | E29: =Data!F162 -> 0
B30: 6 | C30: Mobile / Telephone / Internet | D30: =Data!E163 -> 0 | E30: =Data!F163 -> 0
C31: Sub-total of Household Expenses | D31: =SUM(D25:D30) -> 0 | E31: =SUM(E25:E30) -> 0 | F31: =Data!G164 -> #DIV/0!
B32: Lifestyle Expenses
B33: 1 | C33: Clothes & Accessories | D33: =Data!E166 -> 0 | E33: =Data!F166 -> 0
B34: 2 | C34: Shopping, Gifts, Whitegoods, Gadgets | D34: =Data!E167 -> 0 | E34: =Data!F167 -> 0
B35: 3 | C35: Dining / Movies / Sports | D35: =Data!E168 -> 0 | E35: =Data!F168 -> 0
B36: 4 | C36: Coach - Financial, Fitness, Personal | D36: =Data!E169 -> 0 | E36: =Data!F169 -> 0
B37: 5 | C37: Travel & Annual Vacations | D37: =Data!E170 -> 0 | E37: =Data!F170 -> 0
C38: Lifestyle Expenses | D38: =SUM(D33:D37) -> 0 | E38: =SUM(E33:E37) -> 0 | F38: =Data!G171 -> #DIV/0!
B39: Dependent Expenses
B40: 1 | C40: Children's Schooling/College | D40: =Data!E173 -> 0 | E40: =Data!F173 -> 0
B41: 2 | C41: Contribution to Parents, Siblings etc | D41: =Data!E174 -> 0 | E41: =Data!F174 -> 0
C42: Dependent Expenses | D42: =SUM(D40:D41) -> 0 | E42: =SUM(E40:E41) -> 0 | F42: =Data!G175 -> #DIV/0!
B43: Insurance Premiums
...

Sheet Networth
B1: Networth Statement
B2: Assets
B3: S No | C3: Particulars | D3: Total | E3: Purpose / Goal | F3: % of Assets
B4: Liquid Assets
B5: 1 | C5: Savings Bank/Cash in Hand | D5: =SUM(Data!E225:G225) -> 0
B6: 2 | C6: Receivables | D6: =SUM(Data!E226:G226) -> 0
C7: Total Liquid Assets | D7: =SUM(Data!E227:G227) -> 0 | F7: =D7/$D$37 -> #DIV/0!
B8: Debt Assets | C8: Debt
B9: 1 | C9: Fixed Deposits | D9: =SUM(Data!E229:G229) -> 0
B10: 2 | C10: PPF (Public Provident Fund) | D10: =SUM(Data!E230:G230) -> 0
B11: 3 | C11: EPF + SA + Gratuity | D11: =SUM(Data!E231:G231) -> 0
B12: 4 | C12: NSC / POMIS / KVP / RDs etc | D12: =SUM(Data!E232:G232) -> 0
B13: 5 | C13: Debt Mutual Funds | D13: =SUM(Data!E233:G233) -> 0
B14: 6 | C14: Traditional Insurance Policies SV | D14: =SUM(Data!E234:G234) -> 0
B15: 7 | C15: Bonds/Debentures/CDs | D15: =SUM(Data!E235:G235) -> 0
C16: Total Debt Assets | D16: =SUM(Data!E236:G236) -> 0 | F16: =D16/$D$37 -> #DIV/0!
B17: Equity Assets
B18: 1 | C18: Direct Equity | D18: =SUM(Data!E238:G238) -> 0
B19: 2 | C19: Equity Mutual Funds | D19: =SUM(Data!E239:G239) -> 0
B20: 3 | C20: Unit-linked Insurance SV | D20: =SUM(Data!E240:G240) -> 0
C21: Total Equity Assets | D21: =SUM(Data!E241:G241) -> 0 | F21: =D21/$D$37 -> #DIV/0!
B22: Gold Assets
B23: 1 | C23: ETFs/ Mutual Funds | D23: =SUM(Data!E243:G243) -> 0
B24: 2 | C24: Gold Bars / Coins etc | D24: =SUM(Data!E244:G244) -> 0
C25: Total Gold | D25: =SUM(Data!E245:G245) -> 0 | F25: =D25/$D$37 -> #DIV/0!
B26: Real Estate Assets
B27: 1 | C27: Apartment / House | D27: =SUM(Data!E247:G247) -> 0
B28: 2 | C28: Plot / Land / Holiday Home | D28: =SUM(Data!E248:G248) -> 0
B29: 3 | C29: Real Estate Funds / REITs | D29: =SUM(Data!E249:G249) -> 0
C30: Real Estate | D30: =SUM(Data!E250:G250) -> 0 | F30: =D30/$D$37 -> #DIV/0!
B31: Personal Assets
B32: 1 | C32: Residential Property | D32: =SUM(Data!E257:G257) -> 0
B33: 2 | C33: Vehicles | D33: =SUM(Data!E258:G258) -> 0
B34: 3 | C34: Jewellery | D34: =SUM(Data!E259:G259) -> 0
C35: Total Personal Assets | D35: =SUM(Data!E260:G260) -> 0 | F35: =D35/$D$37 -> #DIV/0!
C37: Total Assets | D37: =D7+D16+D21+D25+D30+D35 -> 0 | F37: =D37/$D$37 -> #DIV/0!
B39: Liabilities
B40: 1 | C40: Home Loan | D40: =Data!D264 -> 0
B41: 2 | C41: Vehicle Loan | D41: =Data!D265 -> 0
B42: 3 | C42: Personal Loan | D42: =Data!D266 -> 0
...

Sheet Insurance
B1: Current General Insurance Policies
B2: S. No. | C2: Type | D2: Policy Name | E2: Sum Insured | F2: Annual Premium | G2: Insured | H2: End / Renewal Date | I2: Recommendation
B3: 1 | C3: Health Insurance
B4: 2 | C4: Critical Illness
B5: 3 | C5: Personal Accident
B6: 4 | C6: Householders Policy
B7: 5 | C7: Home Loan Assurance
B8: 6 | C8: Motor Insurance | I8: Continue
B9: 7 | C9: Group Mediclaim
B10: 8 | C10: Group Personal Accident
C11: Total Premium | F11: =SUM(F3:F10) -> 0

Sheet Policies
B1: Current Life Insurance Policies
B2: S No | C2: Policy Name | D2: Type | E2: Premium (pa) | F2: PPT | G2: Start Date | H2: Maturity Date | I2: Life Cover | J2: Surrender Value | K2: Maturity Value
B3: =Data!D39 -> 0
B4: 1
B5: 2
C6: Total | E6: =SUM(E4:E5) -> 0 | I6: =SUM(I4:I5) -> 0 | J6: =SUM(J4:J5) -> 0 | K6: =SUM(K4:K5) -> 0
B7: =Data!F39 -> 0
B8: 1
B9: 2
C10: Total | E10: =SUM(E8:E9) -> 0 | I10: =SUM(I8:I9) -> 0 | J10: =SUM(J8:J9) -> 0 | K10: =SUM(K8:K9) -> 0
B11: =Data!D49 -> 0
B12: 1
B13: 2
C14: Total | E14: =SUM(E12:E13) -> 0 | I14: =SUM(I12:I13) -> 0 | J14: =SUM(J12:J13) -> 0 | K14: =SUM(K12:K13) -> 0
B15: =Data!E49 -> 0
B16: 1
B17: 2
C18: Total | E18: =SUM(E16:E17) -> 0 | I18: =SUM(I16:I17) -> 0 | J18: =SUM(J16:J17) -> 0 | K18: =SUM(K16:K17) -> 0

Sheet Deposits
B1: Current Deposits
B2: S No. | C2: Instrument | D2: Investment Date | E2: Investment Value | F2: Interest % | G2: Current Value | H2: Maturity Date | I2: Maturity Value
B3: Bank Deposits
B4: 1
B5: 2
B6: 3
B7: Post Office Deposits
B8: 1
B9: 2
B10: 3
B11: Company Deposits
B12: 1
B13: 2
B14: 3
C15: Total | E15: =SUM(E4:E14) -> 0 | G15: =SUM(G4:G14) -> 0

Sheet MF
B1: Current Mutual Funds
B2: Sr. No | C2: Fund Name | D2: Ongoing SIP Amount | E2: Investment Value | F2: Current Value
B3: Equity Mutual Funds
B4: 1
B5: 2
B6: 3
B7: 4
B8: 5
B9: 6
B10: 7
B11: 8
B12: 9
B13: 10
C14: Total Equity Funds | D14: =SUM(D4:D13) -> 0 | E14: =SUM(E4:E13) -> 0 | F14: =SUM(F4:F13) -> 0
B15: Debt-Oriented Mutual Funds
B16: 1
B17: 2
B18: 3
B19: 4
C20: Total Debt Funds | E20: =SUM(E16:E19) -> 0 | F20: =SUM(F16:F19) -> 0

Sheet Equity
B1: Current Equity Shares Portfolio
B2: Sr. No. | C2: Script Name | D2: No of Shares | E2: Investment Value | F2: Current Value
B3: 1
B4: 2
B5: 3
B6: 4
B7: 5
B8: 6
B9: 7
B10: 8
B11: 9
B12: 10
B13: 11
B14: 12
B15: 13
C16: Total | E16: =SUM(E3:E15) -> 0 | F16: =SUM(F3:F15) -> 0

Sheet Future
A1: Future Goals
B19: S. No. | C19: Section
B20: 1 | C20: =Contents!C17 -> Financial Plan Assumptions
B21: 2 | C21: =Contents!C18 -> Life Insurance Needs
B22: 3 | C22: =Contents!C19 -> Complete Insurance Portfolio
B23: 4 | C23: =Contents!C20 -> Contingency Funding
B24: 5 | C24: =Contents!C21 -> Child 1 Future - Child-1
B25: 6 | C25: =Contents!C22 -> Child 2 Future - Child-2
B26: 7 | C26: =Contents!C23 -> Retirement Consultancy
B27: 8 | C27: =Contents!C24 -> House Purchase
B28: 9 | C28: =Contents!C25 -> Car Purchase
B29: 10 | C29: =Contents!C26 -> International Vacation

Sheet Assumptions
B1: Assumptions & Asset Allocation
B2: S.No. | C2: Assumption | D2: Sub-category | F2: Figure | G2: Sub-category | I2: Figure
B3: 1 | C3: Inflation | D3: General Inflation | F3: =Data!E273 -> 0.07 | G3: Education Inflation | I3: =Data!G273 -> 0.1
B4: =B3+1 -> 2 | C4: Income Growth | D4: =Family!D3 -> 0 | F4: =Data!E274 -> 0.07 | G4: =Family!E3 -> 0 | I4: =Data!G274 -> 0
B5: =B4+1 -> 3 | C5: Retirement Age | D5: =Family!D3 -> 0 | F5: =Data!E275 -> 60 | G5: =Family!E3 -> 0 | I5: =Data!G275 -> NA
B6: =B5+1 -> 4 | C6: Life Expectency | D6: =Family!D3 -> 0 | F6: =Data!E276 -> 80 | G6: =Family!E3 -> 0 | I6: =Data!G276 -> 80
B7: =B6+1 -> 5 | C7: Tax Bracket | D7: =Family!D3 -> 0 | F7: =Data!E277 -> 0.3 | G7: Spouse | I7: =Data!G277 -> NA
B8: =B7+1 -> 6 | C8: Loan Rates | D8: Home Loan | F8: =Data!E278 -> 0.08 | G8: Vehicle Loan | I8: =Data!G278 -> 0.11
D9: Education Loan | F9: =Data!E279 -> 0.12 | G9: Personal Loan | I9: =Data!G279 -> 0.18
B10: =B8+1 -> 7 | C10: Asset Class Returns | D10: Liquid | F10: =Data!E280 -> 0.05 | G10: Real Estate | I10: =Data!G280 -> 0.07
D11: Debt | F11: =Data!E281 -> 0.07 | G11: Equity | I11: =Data!G281 -> 0.11
D12: Gold | F12: =Data!E282 -> 0.06
B14: Asset Allocation Assumptions (Based on Time Horizon of Goal)
B15: S.N. | C15: Particulars | D15: Liquid | E15: Debt | F15: Gold | G15: Real Estate | H15: Equity | I15: Total
B16: Average Returns | D16: =F10 -> 0.05 | E16: =F11 -> 0.07 | F16: =F12 -> 0.06 | G16: =I10 -> 0.07 | H16: =I11 -> 0.11 | I16: NA
B17: Very Short Term | C17: 0-1 Year | D17: 0.6 | E17: 0.4 | F17: 0 | G17: 0 | H17: 0 | I17: =SUM(D17:H18) -> 1
I18: =SUMPRODUCT($D$16:$H$16,$D17:$H17) -> 0.058
B19: Short Term | C19: 1-3 Years | D19: 0.2 | E19: 0.8 | F19: 0 | G19: 0 | H19: 0 | I19: =SUM(D19:H20) -> 1
I20: =SUMPRODUCT($D$16:$H$16,$D19:$H19) -> 0.066
B21: Medium Term | C21: 3-6 Years | D21: 0 | E21: 0.6 | F21: 0 | G21: 0 | H21: 0.4 | I21: =SUM(D21:H22) -> 1
I22: =SUMPRODUCT($D$16:$H$16,$D21:$H21) -> 0.086
B23: Long Term | C23: 6-10 Years | D23: 0 | E23: 0.2 | F23: 0 | G23: 0 | H23: 0.8 | I23: =SUM(D23:H24) -> 1
I24: =SUMPRODUCT($D$16:$H$16,$D23:$H23) -> 0.102
B25: Very Long Term | C25: 10+ Years | D25: 0 | E25: 0.1 | F25: 0 | G25: 0 | H25: 0.9 | I25: =SUM(D25:H26) -> 1
I26: =SUMPRODUCT($D$16:$H$16,$D25:$H25) -> 0.106
B27: Income Generation | C27: Retirement | D27: 0.1 | E27: 0.65 | F27: 0 | G27: 0 | H27: 0.25 | I27: =SUM(D27:H28) -> 1
I28: =SUMPRODUCT($D$16:$H$16,$D27:$H27) -> 0.078
C29: Insurance | D29: 0.1 | E29: 0.6 | F29: 0 | G29: 0 | H29: 0.3 | I29: =SUM(D29:H30) -> 1
I30: =SUMPRODUCT($D$16:$H$16,$D29:$H29) -> 0.08

Sheet Life
B1: Life Insurance Needs
B2: Client Goal / Requirement
B3: You would like to protect your family's lifestyle, fulfil current liabilities and commitments in case of pre-mature death.
B5: Sr. No. | C5: Particulars | D5: Amount
B6: Outstanding Liability
B7: 1 | C7: Home Loan | D7: =Networth!D40 -> 0
B8: 2 | C8: Vehicle Loan | D8: =Networth!D41 -> 0
B9: 3 | C9: Personal Loan | D9: =Networth!D42 -> 0
B10: 4 | C10: Education Loan | D10: =Networth!D43 -> 0
B11: A | C11: Total Outstanding Liability | D11: =SUM(D7:D10) -> 0
B12: Family Goals & Commitments
B13: 1 | C13: Children's Education & Marriage | D13: =SUM(Child1!D8:F8)+SUM(Child2!D8:F8) -> 0
B14: 2 | C14: Children's Primary Education | D14: =Cashflow!E40*13 -> 0
B15: 3 | C15: Contribution to Dependents | D15: 0
B16: 4 | C16: House Purchase (First House only) | D16: 0
B17: B | C17: Total Family Goals & Commitments | D17: =SUM(D13:D16) -> 0
B18: Corpus for Regular Expenses
B19: 1 | C19: Household Expenses | D19: =Cashflow!E31+Cashflow!E45 -> 0
B20: 2 | C20: Lifestyle Expenses | D20: =Cashflow!E38 -> 0
B21: 3 | C21: Total Expenses | D21: =SUM(D19:D20) -> 0
B22: 4 | C22: Discounting Factor | D22: 0
B23: 5 | C23: Current Annual Expenses | D23: =D21*(1-D22) -> 0
B24: 6 | C24: Remaining Life of Spouse | D24: =Assumptions!I6-Family!E5 -> 80
B25: 7 | C25: Inflation Rate | D25: =Inflation -> 0.07
B26: 8 | C26: Net Tax on Investment Income | D26: 0
B27: 9 | C27: Investment Returns on insurance claim | D27: =Assumptions!I30 -> 0.08
B28: 10 | C28: Tax Adjusted Returns | D28: =D27*(1-D26) -> 0.08
B29: 11 | C29: Net Returns (Real Rate of Return) | D29: =(1+D28)/(1+D25)-1 -> 0.0093457944
B30: C | C30: Corpus for Regular Expenses in Future | D30: =PV(D29,D24,-D23,,1) -> 0
B31: A+B+C | C31: Total Life Insurance Required | D31: =D11+D17+D30 -> 0
B32: Current Resources Available
B33: 1 | C33: Life Insurance Sum Assured (on Husband) | D33: =Policies!I6 -> 0
B34: 2 | C34: Current Investment Assets (Less SV of Client) | D34: =Networth!D37-Networth!D35-Policies!J6 -> 0
B35: 3 | C35: Present Value of Future Earnings by Spouse | D35: =IFERROR(PV(Assumptions!I4,Assumptions!I5-Family!E5,-Data!F152),0) -> 0
C36: Total Resources Available (E) | D36: =SUM(D33:D35) -> 0
C37: Additional Cover Required | D37: =D31-D36 -> 0
C38: Approximate Premium for Cover Required
B40: Financial Consultant Recommendations

Sheet General
B1: Complete Insurance Portfolio
B2: Client Goal / Requirement
B3: Your family would like to get insured for all possible emergencies in the most cost effective way so that your family is financially secured in case of unforseen situation.
B7: Sr. No. | C7: Type | D7: Cover Amount | E7: For | F7: Approx. Annual Premium
B8: 1 | C8: Life Insurance
B9: 2 | C9: Health Insurance
B10: 3 | C10: Critical Illness
B11: 4 | C11: Personal Accident
B12: 5 | C12: Motor Insurance
B13: 6 | C13: Home Insurance
C14: Total Premium | F14: =SUM(F8:F13) -> 0
B16: Financial Consultant Recommendations

Sheet Contingency
B1: Contingency Fund
B2: Client Goal / Requirement
B3: You would like to build and maintain emergency funds in case of emergencies like job loss, business loss, hospitalization of family members, unplanned purchases or other unforseen expenses.
B6: Sr. No | C6: Particulars | D6: Amount
B7: Current Monthly Expenses
B8: 1 | C8: =Cashflow!B24 -> Household Expenses | D8: =Cashflow!D31 -> 0
B9: 2 | C9: =Cashflow!B32 -> Lifestyle Expenses | D9: =Cashflow!D38 -> 0
B10: 3 | C10: =Cashflow!B39 -> Dependent Expenses | D10: =Cashflow!D42 -> 0
B11: 4 | C11: =Cashflow!B43 -> Insurance Premiums | D11: =Cashflow!D46 -> 0
B12: 5 | C12: =Cashflow!B47 -> Loan Servicing | D12: =Cashflow!D51 -> 0
C13: Total Monthly Expenses | D13: =SUM(D8:D12) -> 0
B14: Monthly Running Expenses
B15: 1 | C15: No. of Months Expenses in Savings Account | D15: 3
B16: 2 | C16: Savings Bank Balance Required | D16: =D13*D15 -> 0
C17: Savings Bank Balance Suggested (Round-Off) | D17: =ROUND(D16,-4) -> 0
B18: Emergency Fund Requirement
B19: 1 | C19: Emergency Months to be Preprared for | D19: 6
B20: 2 | C20: Emergency Funds Required | D20: =D13*D19 -> 0
B21: 3 | C21: Emergency Fund Required (Round-Off) | D21: =ROUND(D20,-4) -> 0
B22: Existing Assets towards Monthly Expenses + Emergency Funds
B23: 1
B24: 2
C25: Total Existing Assets | D25: =SUM(D23:D24) -> 0
B26: Fresh Savings Required
B27: 1 | C27: Deficit (Funds Required-Assets Utilized) | D27: =D17+D21-D25 -> 0
B28: 2 | C28: No. of Months in Savings Period | D28: 18
C29: Monthly Savings Required | D29: =D27/D28 -> 0
B31: Financial Consultant Recommendations

Sheet Child1
B1: =CONCATENATE(Family!F3,"'s Future") -> 0's Future
B2: Client Goal
B3: You would like to arrange 10 Lakhs for Graduation at 18 and 10 lakhs for his PG at 22 and 5 lakhs for Marriage at 26 in today's value.
B6: Sr. No | C6: Details | D6: Graduation | E6: PG | F6: Marriage
B7: Present Value of Goals
B8: 1 | C8: Present Value of Goal | D8: =Data!D66 -> 0 | E8: =Data!E66 -> 0 | F8: =Data!F66 -> 0
B9: 2 | C9: Goal Age | D9: =Data!D65 -> 0 | E9: =Data!E65 -> 0 | F9: =Data!F65 -> 0
B10: 3 | C10: Current Age | D10: =Family!$F$5 -> 0 | E10: =Family!$F$5 -> 0 | F10: =Family!$F$5 -> 0
B11: 4 | C11: Remaining Years for Goal | D11: =D9-D10 -> 0 | E11: =E9-E10 -> 0 | F11: =F9-F10 -> 0
B12: 5 | C12: Goal Planning Year | D12: =YEAR(PlanDate) -> 1900 | E12: =YEAR(PlanDate) -> 1900 | F12: =YEAR(PlanDate) -> 1900
B13: 6 | C13: Goal Target Year | D13: =D12+D11 -> 1900 | E13: =E12+E11 -> 1900 | F13: =F12+F11 -> 1900
B14: 7 | C14: Expected Inflation of Expenses | D14: =Assumptions!$I$3 -> 0.1 | E14: =Assumptions!$I$3 -> 0.1 | F14: =Inflation -> 0.07
B15: 8 | C15: Future Value of Goal | D15: =FV(D14,D11,,-D8) -> 0 | E15: =FV(E14,E11,,-E8) -> 0 | F15: =FV(F14,F11,,-F8) -> 0
B16: Utilization of Current Assets
B17: 1
B18: 2
B19: 3
B20: 4
B21: 5
B22: 6 | C22: Current Assets Utilized | D22: =SUM(D17:D20) -> 0 | E22: =SUM(E17:E20) -> 0 | F22: =SUM(F17:F20) -> 0
B23: 7 | C23: Percentage of Goal on Track | D23: =D22/D15 -> #DIV/0! | E23: =E22/E15 -> #DIV/0! | F23: =F22/F15 -> #DIV/0!
B24: Fresh Investments Required
B25: 1 | C25: Deficit (Amount Required-Assets Utilized) | D25: =D15-D22 -> 0 | E25: =E15-E22 -> 0 | F25: =F15-F22 -> 0
B26: 2 | C26: Start investment after (no. of years)
B27: 3 | C27: Expected Investment Returns | D27: =IF(D$11<=1,Assumptions!$I$18,IF(D$11<=3,Assumptions!$I$20,IF(D$11<=6,Assumptions!$I$22,IF(D$11<=10,Assumptions!$I$24,Assumptions!$I$26)))) -> 0.058 | E27: =IF(E$11<=1,Assumptions!$I$18,IF(E$11<=3,Assumptions!$I$20,IF(E$11<=6,Assumptions!$I$22,IF(E$11<=10,Assumptions!$I$24,Assumptions!$I$26)))) -> 0.058 | F27: =IF(F$11<=1,Assumptions!$I$18,IF(F$11<=3,Assumptions!$I$20,IF(F$11<=6,Assumptions!$I$22,IF(F$11<=10,Assumptions!$I$24,Assumptions!$I$26)))) -> 0.058
B28: 4 | C28: Lumpsum Funding Required (If Available) | D28: =PV(D27,D11,,-D25) -> 0 | E28: =PV(E27,E11,,-E25) -> 0 | F28: =PV(F27,F11,,-F25) -> 0
B29: 5 | C29: Monthly Investments (Fixed) | D29: =-PMT(NOMINAL(D27,12)/12,(D11-D26)*12,,D25,1) -> #NUM! | E29: =-PMT(NOMINAL(E27,12)/12,(E11-E26)*12,,E25,1) -> #NUM! | F29: =-PMT(NOMINAL(F27,12)/12,(F11-F26)*12,,F25,1) -> #NUM!
B30: 6 | C30: StepUp Rate | D30: 0 | E30: 0 | F30: 0
B31: 7 | C31: Monthly Investments (StepUp SIP) | D31: =-PMT(NOMINAL(D27,12)/12,12,,(D25*(D27-D30))/((1+D27)^(D11-D26)-(1+D30)^(D11-D26)),1) -> #DIV/0! | E31: =-PMT(NOMINAL(E27,12)/12,12,,(E25*(E27-E30))/((1+E27)^(E11-E26)-(1+E30)^(E11-E26)),1) -> #DIV/0! | F31: =-PMT(NOMINAL(F27,12)/12,12,,(F25*(F27-F30))/((1+F27)^(F11-F26)-(1+F30)^(F11-F26)),1) -> #DIV/0!
B33: Financial Consultant Recommendations

Sheet Child2
B1: =CONCATENATE(Family!G3,"'s Future") -> 0's Future
B2: Client Goal / Requirement
B3: You would like to arrange 10 Lakhs for Graduation at 18 and 10 lakhs for her PG at 22 and 5 lakhs for Marriage at 26 in today's value.
B6: Sr. No | C6: Details | D6: Graduation | E6: PG | F6: Marriage
B7: Future Value of Goals
B8: 1 | C8: Present Value of Goal | D8: =Data!D73 -> 0 | E8: =Data!E73 -> 0 | F8: =Data!F73 -> 0
B9: 2 | C9: Goal Age | D9: =Data!D72 -> 0 | E9: =Data!E72 -> 0 | F9: =Data!F72 -> 0
B10: 3 | C10: Current Age | D10: =Family!$G$5 -> 0 | E10: =Family!$G$5 -> 0 | F10: =Family!$G$5 -> 0
B11: 4 | C11: Remaining Years for Goal | D11: =D9-D10 -> 0 | E11: =E9-E10 -> 0 | F11: =F9-F10 -> 0
B12: 5 | C12: Goal Planning Year | D12: =YEAR(PlanDate) -> 1900 | E12: =YEAR(PlanDate) -> 1900 | F12: =YEAR(PlanDate) -> 1900
B13: 6 | C13: Goal Target Year | D13: =D12+D11 -> 1900 | E13: =E12+E11 -> 1900 | F13: =F12+F11 -> 1900
B14: 7 | C14: Expected Inflation of Expenses | D14: =Assumptions!$I$3 -> 0.1 | E14: =Assumptions!$I$3 -> 0.1 | F14: =Inflation -> 0.07
B15: 8 | C15: Future Value of Goal | D15: =FV(D14,D11,,-D8) -> 0 | E15: =FV(E14,E11,,-E8) -> 0 | F15: =FV(F14,F11,,-F8) -> 0
B16: Utilization of Current Assets
B17: 1
B18: 2
B19: 3
B20: 4 | C20: Current Assets Utilized | D20: =SUM(D17:D19) -> 0 | E20: =SUM(E17:E19) -> 0 | F20: =SUM(F17:F19) -> 0
B21: 5 | C21: Percentage of Goal on Track | D21: =D20/D15 -> #DIV/0! | E21: =E20/E15 -> #DIV/0! | F21: =F20/F15 -> #DIV/0!
B22: Fresh Investments Required
B23: 1 | C23: Deficit (Amount Required-Assets Utilized) | D23: =D15-D20 -> 0 | E23: =E15-E20 -> 0 | F23: =F15-F20 -> 0
B24: 2 | C24: Start investment after (no. of years)
B25: 3 | C25: Expected Investment Returns | D25: =IF(D$11<=1,Assumptions!$I$18,IF(D$11<=3,Assumptions!$I$20,IF(D$11<=6,Assumptions!$I$22,IF(D$11<=10,Assumptions!$I$24,Assumptions!$I$26)))) -> 0.058 | E25: =IF(E$11<=1,Assumptions!$I$18,IF(E$11<=3,Assumptions!$I$20,IF(E$11<=6,Assumptions!$I$22,IF(E$11<=10,Assumptions!$I$24,Assumptions!$I$26)))) -> 0.058 | F25: =IF(F$11<=1,Assumptions!$I$18,IF(F$11<=3,Assumptions!$I$20,IF(F$11<=6,Assumptions!$I$22,IF(F$11<=10,Assumptions!$I$24,Assumptions!$I$26)))) -> 0.058
B26: 4 | C26: Lumpsum Investments | D26: =PV(D25,D11,,-D23) -> 0 | E26: =PV(E25,E11,,-E23) -> 0 | F26: =PV(F25,F11,,-F23) -> 0
B27: 5 | C27: Monthly Investments (Fixed) | D27: =-PMT(NOMINAL(D25,12)/12,(D11-D24)*12,,D23,1) -> #NUM! | E27: =-PMT(NOMINAL(E25,12)/12,(E11-E24)*12,,E23,1) -> #NUM! | F27: =-PMT(NOMINAL(F25,12)/12,(F11-F24)*12,,F23,1) -> #NUM!
B28: 6 | C28: StepUp Rate | D28: 0 | E28: 0 | F28: 0
B29: 7 | C29: Monthly Investments (StepUp SIP) | D29: =-PMT(NOMINAL(D25,12)/12,12,,(D23*(D25-D28))/((1+D25)^(D11-D24)-(1+D28)^(D11-D24)),1) -> #DIV/0! | E29: =-PMT(NOMINAL(E25,12)/12,12,,(E23*(E25-E28))/((1+E25)^(E11-E24)-(1+E28)^(E11-E24)),1) -> #DIV/0! | F29: =-PMT(NOMINAL(F25,12)/12,12,,(F23*(F25-F28))/((1+F25)^(F11-F24)-(1+F28)^(F11-F24)),1) -> #DIV/0!
B31: Financial Consultant Recommendations

Sheet Retirement
B1: Retirement Analysis
B2: Client Goal / Requirement
B3: You would like to accumulate an investment corpus to fund your retirement expenses from age 60 to 80.
B6: Sr. No | C6: Particulars | D6: Amount
B7: Current Annual Expenses
B8: 1 | C8: Household Expenses | D8: =Cashflow!D31 -> 0
B9: 2 | C9: Lifestyle Expenses | D9: =Cashflow!D38 -> 0
B10: 3 | C10: Insurance Expenses Post Retirement (if any) | D10: 0
B11: 4 | C11: Any Other Expenses (5-10% of total expenses) | D11: 0
C12: Total Monthly Expenses | D12: =SUM(D8:D11) -> 0
C13: Total Annual Expenses | D13: =D12*12 -> 0
B14: Your Future Annual Expenses
B15: 1 | C15: Current Age | D15: =Age -> 0
B16: =B15+1 -> 2 | C16: Retirement Age | D16: =Data!F90 -> 0
B17: =B16+1 -> 3 | C17: No. of Years for Retirement | D17: =D16-D15 -> 0
B18: =B17+1 -> 4 | C18: Inflation | D18: =Inflation -> 0.07
B19: =B18+1 -> 5 | C19: Drop in Expenses after Retirement | D19: 0
C20: Annual Expenses @ Retirement Age | D20: =FV(D18,D17,,-D13*(1-D19)) -> 0
C21: Monthly Expenses @ Retirement Age | D21: =D20/12 -> 0
B22: Investment Corpus Required
B23: 1 | C23: Life Expectancy Age | D23: =Data!F91 -> 0
B24: 2 | C24: No. of Years Post Retirement | D24: =D23-D16 -> 0
B25: 3 | C25: Inflation during Retirement Years | D25: =Inflation -> 0.07
B26: 4 | C26: Net Tax on Investment Income | D26: 0
B27: 5 | C27: Investment Returns on Retirement Corpus | D27: =Assumptions!I28 -> 0.078
B28: 6 | C28: Tax Adjusted Returns | D28: =D27*(1-D26) -> 0.078
B29: 7 | C29: Real Returns (Inflation & Tax Adjusted) | D29: =(1+D28)/(1+D25)-1 -> 0.0074766355
C30: Retirement Corpus | D30: =PV(D29,D24,-D20,,1) -> 0
B31: Future Value of Current Assets Utilized
B32: 1
B33: =B32+1 -> 2
B34: =B33+1 -> 3
B35: 4 | C35: Total Employment Benefits @ Retirement Age | D35: =SUM(D32:D34) -> 0
B36: 5 | C36: Percentage of Goal on Track | D36: =D35/D30 -> #DIV/0!
B37: Fresh Investments Required
B38: 1 | C38: Deficit (Amount Required-Assets Utilized) | D38: =D30-D35 -> 0
B39: 2 | C39: Start investment after (no. of years)
B40: 3 | C40: Expected Investment Returns | D40: =IF(D$17<=1,Assumptions!$I$18,IF(D$17<=3,Assumptions!$I$20,IF(D$17<=6,Assumptions!$I$22,IF(D$17<=10,Assumptions!$I$24,Assumptions!$I$26)))) -> 0.058
B41: 4 | C41: Lumpsum Funding Required (If Available) | D41: =PV(D40,D17,,-D38) -> 0
C42: Monthly Investments (Fixed SIP) | D42: =PMT(NOMINAL(D40,12)/12,(D17-D39)*12,,-D38,1) -> #NUM!
...

Sheet House
B1: House Purchase
B2: Client Goal / Requirement
B3: You would like to purchase a 2 BHK flat in the next 4 years costing around 60 lakhs in today's value in Navi Mumbai
B6: Sr. No | C6: Particulars | D6: Amount
B7: Future Value of House
B8: 1 | C8: Present Value of House | D8: =Data!E82*Data!E83 -> 0
B9: 2 | C9: Additional Costs (Reg. charges, Interiors, Taxes, etc) | D9: =Data!E84 -> 0
B10: 3 | C10: Total Present Value of House | D10: =D8*(1+D9) -> 0
B11: 4 | C11: Growth Rate of Real Estate (Assumption) | D11: =Assumptions!I10 -> 0.07
B12: 5 | C12: Number of Years for Goal | D12: =Data!G80 -> 0
B13: 6 | C13: Future Value of House | D13: =FV(D11,D12,,-D10) -> 0
B14: 7 | C14: Future Value Of House (excl. additional costs for loan purpose) | D14: =FV(D11,D12,,-D8,1) -> 0
B15: Home Loan / Downpayment | C15: Funding of Goal
B16: 1 | C16: Home Loan Funding | D16: =Data!G83 -> 0
B17: 2 | C17: Home Loan Amount | D17: =D13*D16 -> 0
B18: 3 | C18: Down-Payment Funding (for loan) | D18: =1-D16 -> 1
B19: 4 | C19: Down-Payment Amount | D19: =D13*D18 -> 0
B20: 5 | C20: Total Amount to be accumulated (incl. additional costs) | D20: =D19+D13-D14 -> 0
B21: Home Loan Feasibilty
B22: 1 | C22: Current Monthly Income | D22: =Cashflow!D9 -> 0
B23: 2 | C23: Expected Monthly Income while buying | D23: =FV(Assumptions!F4,D12,,-D22,0) -> 0
B24: 3 | C24: Ideal Percentage of EMI to Monthly Income | D24: 0.5
B25: 4 | C25: Ideal Home Loan EMI Limit | D25: =D24*D23 -> 0
B26: 5 | C26: Home Loan Rate | D26: =Assumptions!F8 -> 0.08
B27: 6 | C27: Home Loan Tenure (in Years) | D27: 20
B28: 7 | C28: Home Loan EMI | D28: =PMT(D26/12,D27*12,-D17) -> 0
B29: Utilization of Current Assets for Down-payment
B30: 1
B31: 2
B32: 3
B33: 4 | C33: Total Current Assets Utilized | D33: =SUM(D30:D32) -> 0
B34: 5 | C34: Percentage of Goal on Track | D34: =D33/D19 -> #DIV/0!
B35: Fresh Investments Required for Down-payment
B36: 1 | C36: Deficit (Amount Required-Assets Utilized) | D36: =D19-D33 -> 0
B37: 2 | C37: Start investment after (no. of years)
B38: 3 | C38: Expected Investment Returns | D38: =IF($D$12<=1,Assumptions!$I$18,IF($D$12<=3,Assumptions!$I$20,IF($D$12<=6,Assumptions!$I$22,IF($D$12<=10,Assumptions!$I$24,Assumptions!$I$26)))) -> 0.058
B39: 4 | C39: Lumpsum Funding Required (If Available) | D39: =PV(D38,D12,,-D36) -> 0
B40: 5 | C40: Monthly Investments (Fixed) | D40: =-PMT(NOMINAL(D38,12)/12,(D12-D37)*12,0,D36,1) -> #NUM!
B41: 6 | C41: StepUp Rate | D41: 0
B42: 7 | C42: Monthly Investments (StepUp SIP) | D42: =-PMT(NOMINAL(D38,12)/12,12,,(D36*(D38-D41))/((1+D38)^(D12-D37)-(1+D41)^(D12-D37)),1) -> #DIV/0!
...

Sheet Car
B1: Car Purchase
B2: Client Goal / Requirement
B3: Your family would like to purchase a car in the next 6 years costing around 8 lakhs in today's value.
B6: Sr. No | C6: Particulars | D6: Amount
B7: Future Value of Car
B8: 1 | C8: Current On Road Price of the Car | D8: =Data!F101 -> 0
B9: 2 | C9: Inflation | D9: =Inflation -> 0.07
B10: 3 | C10: Number of Years for Goal | D10: =Data!F102 -> 0
B11: 4 | C11: Goal Year | D11: =PlanDate+D10*365 -> 0
B12: 5 | C12: Future Value of Car | D12: =FV(D9,D10,,-D8) -> 0
B13: Loan vs. Downpayment
B14: 1 | C14: Vehicle Loan | D14: 0
B15: 2 | C15: Vehicle Loan Amount | D15: =D14*D12 -> 0
B16: 3 | C16: Down-Payment | D16: =1-D14 -> 1
B17: 4 | C17: Down-Payment Amount | D17: =D16*D12 -> 0
B18: Vehicle Loan EMI
B19: 1 | C19: Vehicle Loan Rate | D19: =Assumptions!I8 -> 0.11
B20: 2 | C20: Vehicle Loan Tenure (in Years) | D20: 5
B21: 3 | C21: Vehicle Loan EMI | D21: =PMT(D19/12,D20*12,-D15,,) -> 0
B22: Utilization of Current Assets for Down-payment
B23: 1
B24: 2
B25: 3
B26: 3 | C26: Total Current Assets Utilized | D26: =SUM(D23:D25) -> 0
B27: 4 | C27: Percentage of Goal on Track | D27: =D26/D17 -> #DIV/0!
B28: Fresh Investments Required for Down-payment
B29: 1 | C29: Deficit (Corpus Required-Assets Utilized) | D29: =D17-D26 -> 0
B30: 2 | C30: Start investment after (no. of years)
B31: 3 | C31: Expected Investment Returns | D31: =IF($D$10<=1,Assumptions!$I$18,IF($D$10<=3,Assumptions!$I$20,IF($D$10<=6,Assumptions!$I$22,IF($D$10<=10,Assumptions!$I$24,Assumptions!$I$26)))) -> 0.058
B32: 4 | C32: Lumpsum Funding Required (If Available) | D32: =-PV(D31,D10,,D29) -> 0
B33: 5 | C33: Monthly Investments (Fixed) | D33: =PMT(NOMINAL(D31,12)/12,(D10-D30)*12,,-D29,1) -> #NUM!
B34: 6 | C34: StepUp Rate | D34: 0
B35: 7 | C35: Monthly Investments (Growing) | D35: =-PMT(NOMINAL(D31,12)/12,12,,(D29*(D31-D34))/((1+D31)^(D10-D30)-(1+D34)^(D10-D30)),1) -> #DIV/0!
B37: Planner Comments/Observations

Sheet Vacation
B1: International Vacation
B2: Client Goal / Requirement
B3: Your family would like to go on an international vacation in the next 4 years costing around 3 lakhs in today's value
B6: Sr. No | C6: Particulars | D6: Amount
B7: Future Value of Vacation
B8: 1 | C8: Present Value of the Vacation | D8: =Data!F113 -> 0
B9: 2 | C9: Inflation | D9: =Inflation -> 0.07
B10: 3 | C10: Number of Years for Goal | D10: =Data!F108 -> 0
B11: 4 | C11: Future Cost of Vacation | D11: =FV(D9,D10,,-D8) -> 0
B12: Utilization of Current Assets
B13: 1
B14: 2
B15: 3 | C15: Total Current Assets Utilized | D15: =SUM(D13:D14) -> 0
B16: 4 | C16: Percentage of Goal on Track | D16: =D15/D11 -> #DIV/0!
B17: Fresh Investments Required | C17: Fresh Investments Required
B18: 1 | C18: Deficit (Corpus Required-Assets Utilized) | D18: =D11-D15 -> 0
B19: 2 | C19: Start investment after (no. of years)
B20: 3 | C20: Expected Investment Returns | D20: =IF($D$10<=1,Assumptions!$I$18,IF($D$10<=3,Assumptions!$I$20,IF($D$10<=6,Assumptions!$I$22,IF($D$10<=10,Assumptions!$I$24,Assumptions!$I$26)))) -> 0.058
B21: 4 | C21: Lumpsum Funding Required (If Available) | D21: =-PV(D20,D10,,D18) -> 0
B22: 5 | C22: Monthly Investments Required | D22: =-PMT(NOMINAL(D20,12)/12,(D10-D19)*12,,D18,1) -> #NUM!
B23: 6 | C23: StepUp Rate | D23: 0
B24: 7 | C24: Monthly Investments (Growing) | D24: =-PMT(NOMINAL(D20,12)/12,12,,(D18*(D20-D23))/((1+D20)^(D10-D19)-(1+D23)^(D10-D19)),1) -> #DIV/0!
B26: Planner Comments/Observations

Sheet Life CF
B1: Five Year Cashflow Analysis
B2: S. No. | C2: Particulars | D2: =Data!G34 -> 0 | E2: =D2+365 -> 365 | F2: =E2+365 -> 730 | G2: =F2+365 -> 1095 | H2: =G2+365 -> 1460
B3: Age Schedule
B4: 1 | C4: =Data!D39 -> 0 | D4: =Data!D45 -> 0 | E4: =D4+1 -> 1 | F4: =E4+1 -> 2 | G4: =F4+1 -> 3 | H4: =G4+1 -> 4
B5: 2 | C5: =Data!F39 -> 0 | D5: =Data!F45 -> 0 | E5: =D5+1 -> 1 | F5: =E5+1 -> 2 | G5: =F5+1 -> 3 | H5: =G5+1 -> 4
B6: 3 | C6: =Data!D49 -> 0 | D6: =Data!D54 -> 0 | E6: =D6+1 -> 1 | F6: =E6+1 -> 2 | G6: =F6+1 -> 3 | H6: =G6+1 -> 4
B7: 4 | C7: =Data!E49 -> 0 | D7: =Data!E54 -> 0 | E7: =D7+1 -> 1 | F7: =E7+1 -> 2 | G7: =F7+1 -> 3 | H7: =G7+1 -> 4
B8: Annual Inflows
B9: 1 | C9: Income (Husband) | D9: =Data!E152 -> 0 | E9: =D9*(1+Assumptions!$F$4) -> 0 | F9: =E9*(1+Assumptions!$F$4) -> 0 | G9: =F9*(1+Assumptions!$F$4) -> 0 | H9: =G9*(1+Assumptions!$F$4) -> 0
B10: 2 | C10: Income (Wife) | D10: =Data!F152 -> 0 | E10: =D10*(1+Assumptions!$F$4) -> 0 | F10: =E10*(1+Assumptions!$F$4) -> 0 | G10: =F10*(1+Assumptions!$F$4) -> 0 | H10: =G10*(1+Assumptions!$F$4) -> 0
C11: Total Inflows | D11: =SUM(D9:D10) -> 0 | E11: =SUM(E9:E10) -> 0 | F11: =SUM(F9:F10) -> 0 | G11: =SUM(G9:G10) -> 0 | H11: =SUM(H9:H10) -> 0
B12: Annual Expenses
B13: 1 | C13: Household Expenses | D13: =Data!F164 -> 0 | E13: =D13*(1+Inflation) -> 0 | F13: =E13*(1+Inflation) -> 0 | G13: =F13*(1+Inflation) -> 0 | H13: =G13*(1+Inflation) -> 0
B14: 2 | C14: Lifestyle Expenses | D14: =Data!F171 -> 0 | E14: =D14*(1+Inflation) -> 0 | F14: =E14*(1+Inflation) -> 0 | G14: =F14*(1+Inflation) -> 0 | H14: =G14*(1+Inflation) -> 0
B15: 3 | C15: Children's Schooling/College | D15: =Data!F173 -> 0 | E15: =D15*(1+Inflation) -> 0 | F15: =E15*(1+Inflation) -> 0 | G15: =F15*(1+Inflation) -> 0 | H15: =G15*(1+Inflation) -> 0
B16: 4 | C16: Contribution to Parents, Siblings etc | D16: =Data!F174 -> 0 | E16: =D16*(1+Inflation) -> 0 | F16: =E16*(1+Inflation) -> 0 | G16: =F16*(1+Inflation) -> 0 | H16: =G16*(1+Inflation) -> 0
B17: 5 | C17: Pure Insurance Premiums | D17: =Data!F179 -> 0 | E17: =D17 -> 0 | F17: =E17 -> 0 | G17: =F17 -> 0 | H17: =G17 -> 0
B18: 6 | C18: Loan EMIs | D18: =Data!F184 -> 0 | E18: =D18 -> 0 | F18: =E18 -> 0 | G18: =F18 -> 0 | H18: =G18 -> 0
C19: Total Expenses | D19: =SUM(D13:D18) -> 0 | E19: =SUM(E13:E18) -> 0 | F19: =SUM(F13:F18) -> 0 | G19: =SUM(G13:G18) -> 0 | H19: =SUM(H13:H18) -> 0
C20: Savings (Inflows-Outflows) | D20: =D11-D19 -> 0 | E20: =E11-E19 -> 0 | F20: =F11-F19 -> 0 | G20: =G11-G19 -> 0 | H20: =H11-H19 -> 0
B21: Regular Investments
B22: 1 | C22: Ins. Premiums (Investments) | D22: =Data!F192 -> 0 | E22: =D22 -> 0 | F22: =E22 -> 0 | G22: =F22 -> 0 | H22: =G22 -> 0
B23: 2 | C23: Mutual Fund SIPs | D23: 0 | E23: 0 | F23: 0 | G23: 0 | H23: 0
C24: Current Regular Investments | D24: =SUM(D22:D23) -> 0 | E24: =SUM(E22:E23) -> 0 | F24: =SUM(F22:F23) -> 0 | G24: =SUM(G22:G23) -> 0 | H24: =SUM(H22:H23) -> 0
C25: Current Surplus (Savings-Invts) | D25: =D20-D24 -> 0 | E25: =E20-E24 -> 0 | F25: =F20-F24 -> 0 | G25: =G20-G24 -> 0 | H25: =H20-H24 -> 0
B26: Investment Recommendations (Including current MF SIPs)
B27: 1 | C27: =CONCATENATE(Child1!B1," - ",Child1!D6) -> 0's Future - Graduation
B28: 2 | C28: =CONCATENATE(Child1!B1," - ",Child1!E6) -> 0's Future - PG
B29: 3 | C29: =CONCATENATE(Child1!B1," - ",Child1!F6) -> 0's Future - Marriage
B30: 4 | C30: =CONCATENATE(Child2!B1," - ",Child2!D6) -> 0's Future - Graduation
B31: 5 | C31: =CONCATENATE(Child2!B1," - ",Child2!E6) -> 0's Future - PG | D31: =Child2!E29*12 -> #DIV/0! | E31: =D31*(1+Child2!$E$28) -> #DIV/0! | F31: =E31*(1+Child2!$E$28) -> #DIV/0! | G31: =F31*(1+Child2!$E$28) -> #DIV/0! | H31: =G31*(1+Child2!$E$28) -> #DIV/0!
B32: 6 | C32: =CONCATENATE(Child2!B1," - ",Child2!F6) -> 0's Future - Marriage | D32: =Child2!F29*12 -> #DIV/0! | E32: =D32*(1+Child2!$F$28) -> #DIV/0! | F32: =E32*(1+Child2!$F$28) -> #DIV/0! | G32: =F32*(1+Child2!$F$28) -> #DIV/0! | H32: =G32*(1+Child2!$F$28) -> #DIV/0!
B33: 7 | C33: Contingency Fund | D33: =Contingency!D29*12 -> 0
B34: 8 | C34: Retirement Funding | D34: =Retirement!D44*12 -> #DIV/0! | E34: =D34*(1+Retirement!$D$43) -> #DIV/0! | F34: =E34*(1+Retirement!$D$43) -> #DIV/0! | G34: =F34*(1+Retirement!$D$43) -> #DIV/0! | H34: =G34*(1+Retirement!$D$43) -> #DIV/0!
B35: 9 | C35: House Purchase | D35: =House!D42*12 -> #DIV/0! | E35: =D35*(1+House!$D$41) -> #DIV/0! | F35: =E35*(1+House!$D$41) -> #DIV/0! | G35: =F35*(1+House!$D$41) -> #DIV/0! | H35: =G35*(1+House!$D$41) -> #DIV/0!
B36: 10 | C36: Car Purchase | D36: =Car!D35*12 -> #DIV/0! | E36: =D36*(1+Car!$D$34) -> #DIV/0! | F36: =E36*(1+Car!$D$34) -> #DIV/0! | G36: =F36*(1+Car!$D$34) -> #DIV/0! | H36: =G36*(1+Car!$D$34) -> #DIV/0!
B37: 11 | C37: International Vacation | D37: =Vacation!D24*12 -> #DIV/0! | E37: =D37*(1+Vacation!$D$23) -> #DIV/0! | F37: =E37*(1+Vacation!$D$23) -> #DIV/0! | G37: =F37*(1+Vacation!$D$23) -> #DIV/0! | H37: =G37*(1+Vacation!$D$23) -> #DIV/0!
C38: Total Fresh Investments | D38: =SUM(D27:D37) -> #DIV/0! | E38: =SUM(E27:E37) -> #DIV/0! | F38: =SUM(F27:F37) -> #DIV/0! | G38: =SUM(G27:G37) -> #DIV/0! | H38: =SUM(H27:H37) -> #DIV/0!
B39: Insurance Recommendations
B40: 1 | C40: Life Insurance | D40: =General!F8 -> 0 | E40: =D40 -> 0 | F40: =E40 -> 0 | G40: =F40 -> 0 | H40: =G40 -> 0
...

Sheet Disclaimer
A1: Disclaimer & Disclosure
A2: Disclaimer
A3: A Financial Blueprint is a generic direction to your cash flows over a period of time. Your future financial condition may alter due to changes in income/expense patterns, new family commitments, macro economic scenario etc which may prompt you to alter some aspects of your goals and add new goals. Therefore this Blueprint and the Cashflows depicted in it should be used to give you a long term direction for managing your personal finances while taking immediate actions as a step towards accomplishing your financial objectives.
A5: These recommendations are subject to review at the time when you are actually taking actions as recommended because of changes in legal circumstances, economic conditions etc. If considerable time has elapsed since the date of this plan, you should not act on any specific recommendation without further consideration with the planner.
A7: Returns from each recommended investment will vary in line with market conditions and investment policies of the fund manager. Income and growth assumptions are intended as a guide only and should be treated with caution. The consultant should not be held responsible for the accuracy of the same. Most equity/ growth investment are long term in nature and significant variations including capital loss, may occur over shorter periods. Neither the authorized representative nor the company guarantees the performance or return of capital on any of these investments. Performances of investments are subject to market risks. Past performances of a particular asset class or investment may not be the true indicator of their performance in future.
A9: These recommendations are based on the information you have supplied. If any material information has been withheld or any inaccurate, these recommendations could prove to be inappropriate for you.
A11: While we have made every attempt to ensure that the calculations contained in this Financial Blueprint are correct and complete, kindly note the plan may contain inaccuracies or errors due the manual-computer interface involved in making the calculations and we expressly exclude liability for any such inaccuracies or errors. In the case where a error or omission is involved, you can request us to rectify the error or omission, we shall do needful.
A13: Disclosure
A14: If the product recommendation are implemented through us, we would receive applicable brokerage/commissions/trails from all/some of the investments recommended. We will be entitled to commission directly from product providers. We will be also eligible to other incentives including allowances and incentives based on volumes, discounted services and awards. However these benefits & compensation from the product manufacturers shall be disclosed wherever applicable to you and will not be the basis for any recommendations.

Sheet Sheet1

Sheet Misc
A11: Miscellaneous Sheets

Sheet Products
B1: Product Recommendations
B2: Mutual Funds
B3: S No | C3: Investment Particulars | D3: Investment 1 | E3: Investment 2 | F3: Investment 3 | G3: Investment 4 | H3: Investment 5
B4: 1 | C4: Amount
B5: 2 | C5: Fund Name
B6: 3 | C6: Mode - LS / SIP / SWP / STP
B7: 4 | C7: Option - D / G
B8: 5 | C8: Fund Type
B9: 6 | C9: Risk Profile of Investment
B10: 7 | C10: In Whose Name
B11: 8 | C11: Purpose of Investment
B12: 9 | C12: Source of Investment
B13: 10 | C13: Timeline / Date of Investment
B14: 11 | C14: Proposed Time Horizon of Investment
B15: 12 | C15: Nominee of the Investment
B17: Insurance
B18: S No | C18: Investment Particulars | D18: Investment 1 | E18: Investment 2 | F18: Investment 3 | G18: Investment 4 | H18: Investment 5
B19: 1 | C19: Type of Policy
B20: 2 | C20: Policy Name
B21: 3 | C21: Insurance Company
B22: 4 | C22: Insurance Cover Amount
B23: 5 | C23: Approx Premium Amount
B24: 6 | C24: Source of Premium Amount
B25: 7 | C25: Purpose of Insurance
B26: 8 | C26: Proposed Duration of Policy
B27: 9 | C27: Name of Person getting Insured
B28: 10 | C28: Name of Nominee / Beneficiary

Sheet Graphs
A1: Key Figures in Graphs
B2: Current Asset Allocation
B3: Liquid | C3: =Networth!F7 -> #DIV/0!
B4: Debt | C4: =Networth!F16 -> #DIV/0!
B5: Gold | C5: =Networth!F25 -> #DIV/0!
B6: Equity | C6: =Networth!F21 -> #DIV/0!
B7: Real Estate | C7: =Networth!F30 -> #DIV/0!
B18: Your Networth
B19: Networth | C19: =Networth!D52 -> 0
B20: Total Liabilities | C20: =Networth!D46 -> 0
B21: Total Assets | C21: =Networth!D37 -> 0
B22: Investment Assets | C22: =Networth!D37-Networth!D35 -> 0
B23: Personal Assets | C23: =Networth!D35 -> 0
A32: Key Figures in Graphs
B33: Income Expenditure Statement (p.a.)
B34: Income | C34: =Cashflow!E9 -> 0
B35: Household Expenses | C35: =Cashflow!E31 -> 0
B36: Lifestyle Expenses | C36: =Cashflow!E38 -> 0
B37: Dependents Expenses | C37: =Cashflow!E42 -> 0
B38: Pure Insurance Premiums | C38: =Cashflow!E46 -> 0
B39: Loan Servicing | C39: =Cashflow!E51 -> 0
B40: Savings | C40: =Cashflow!E55 -> 0
B41: Regular Investments | C41: =Cashflow!E18 -> 0
B42: Surplus (Potential Invest.) | C42: =Cashflow!E19 -> 0
B49: Risk Return Assumption
B50: Liquid | C50: =Assumptions!F10 -> 0.05
B51: Debt | C51: =Assumptions!F11 -> 0.07
B52: Gold | C52: =Assumptions!F12 -> 0.06
B53: Real Estate | C53: =Assumptions!I10 -> 0.07
B54: Equity | C54: =Assumptions!I11 -> 0.11
A63: Key Figures in Graphs
B64: Life Insurance Requirement
B65: Current Life Insurance Cover | C65: =Life!D33 -> 0
B66: Current Assets providing cover | C66: =Life!D34 -> 0
B67: Present Value of Future Income of Spouse | C67: =Life!D35 -> 0
B68: Additional Life Insurance Requirement | C68: =Life!D37 -> 0
B80: Retirement Corpus Utilization
B82: Age | C82: Corpus | D82: Annual Expenses | E82: Balance | F82: Balance Growth
B83: =Assumptions!F5+1 -> 61 | C83: =Retirement!D30 -> 0 | D83: =-Retirement!D20 -> 0 | E83: =C83+D83 -> 0 | F83: =E83+E83*Retirement!$D$28 -> 0
B84: =B83+1 -> 62 | C84: =F83 -> 0 | D84: =D83+D83*Inflation -> 0 | E84: =C84+D84 -> 0 | F84: =E84+E84*Retirement!$D$28 -> 0
...

Sheet Asset-Goal
B1: Asset-Goal Mapping Sheet
B2: Sr. No. | C2: List of Goal | D2: Maturity Year | E2: No of Years | F2: Amount Required | G2: Priority | H2: Goal Type | I2: Assets Suitable
B3: 1 | C3: =Funding!C4 -> 0 - Graduation | D3: =YEAR(PlanDate)+E3 -> 1900 | E3: =Funding!E4 -> 0 | F3: =Funding!F4 -> 0 | G3: =Data!D68 -> High | H3: =IF(E3<=3,"Short",IF(E3<=7,"Medium",IF(E3>7,"Long"))) -> Short
B4: 2 | C4: =Funding!C5 -> 0 - Post Grad | D4: =YEAR(PlanDate)+E4 -> 1900 | E4: =Funding!E5 -> 0 | F4: =Funding!F5 -> 0 | G4: =Data!E68 -> High | H4: =IF(E4<=3,"Short",IF(E4<=7,"Medium",IF(E4>7,"Long"))) -> Short
B5: 3 | C5: =Funding!C6 -> 0 - Marriage | D5: =YEAR(PlanDate)+E5 -> 1900 | E5: =Funding!E6 -> 0 | F5: =Funding!F6 -> 0 | G5: =Data!F68 -> Medium | H5: =IF(E5<=3,"Short",IF(E5<=7,"Medium",IF(E5>7,"Long"))) -> Short
B6: 4 | C6: =Funding!C9 -> 0 - Graduation | D6: =YEAR(PlanDate)+E6 -> 1900 | E6: =Funding!E9 -> 0 | F6: =Funding!F9 -> 0 | G6: =Data!D75 -> 0 | H6: =IF(E6<=3,"Short",IF(E6<=7,"Medium",IF(E6>7,"Long"))) -> Short
B7: 5 | C7: =Funding!C10 -> 0 - Post Grad | D7: =YEAR(PlanDate)+E7 -> 1900 | E7: =Funding!E10 -> 0 | F7: =Funding!F10 -> 0 | G7: =Data!E75 -> 0 | H7: =IF(E7<=3,"Short",IF(E7<=7,"Medium",IF(E7>7,"Long"))) -> Short
